2025-03-21 13:47:24,551 : INFO : root : Loading config.
2025-03-21 13:47:24,554 : INFO : YamlMultifileConfigLoader : Machine config file #1: config.yaml
2025-03-21 13:47:24,554 : WARNING : ConfigProcessor : Config file in cache changed: C:\Users\duffb\OneDrive\Documents\Python Envs\PinBallWW1\Machine\config\config.yaml
2025-03-21 13:47:24,554 : INFO : ConfigProcessor : Loading config from file C:\Users\duffb\.pyenv\pyenv-win\versions\3.11.0\Lib\site-packages\mpf\mpfconfig.yaml.
2025-03-21 13:47:24,564 : INFO : ConfigProcessor : Loading config: C:\Users\duffb\.pyenv\pyenv-win\versions\3.11.0\Lib\site-packages\mpf\mpfconfig.yaml
2025-03-21 13:47:24,565 : INFO : ConfigProcessor : Loading config from file C:\Users\duffb\OneDrive\Documents\Python Envs\PinBallWW1\Machine\config\config.yaml.
2025-03-21 13:47:24,585 : INFO : ConfigProcessor : Loading config: C:\Users\duffb\OneDrive\Documents\Python Envs\PinBallWW1\Machine\config\config.yaml
2025-03-21 13:47:24,586 : INFO : ConfigProcessor : Config file cache created: C:\Users\duffb\AppData\Local\Temp\cadfdee4981114acd6fff59d1071b59b.mpf_cache
2025-03-21 13:47:24,687 : INFO : ConfigProcessor : Loading config from cache: C:\Users\duffb\AppData\Local\Temp\ee7db1e8d011f44c876692bb4657f2e9.mpf_cache
2025-03-21 13:47:24,687 : INFO : ConfigProcessor : Loading config from cache: C:\Users\duffb\AppData\Local\Temp\9f058d482eac17116727d62a93500be7.mpf_cache
2025-03-21 13:47:24,689 : WARNING : ConfigProcessor : Config file in cache changed: C:\Users\duffb\OneDrive\Documents\Python Envs\PinBallWW1\Machine\modes\intro\config\intro.yaml
2025-03-21 13:47:24,689 : INFO : ConfigProcessor : Loading config from file C:\Users\duffb\OneDrive\Documents\Python Envs\PinBallWW1\Machine\modes\intro\config\intro.yaml.
2025-03-21 13:47:24,702 : INFO : ConfigProcessor : Loading config: C:\Users\duffb\OneDrive\Documents\Python Envs\PinBallWW1\Machine\modes\intro\config\intro.yaml
2025-03-21 13:47:24,703 : INFO : ConfigProcessor : Config file cache created: C:\Users\duffb\AppData\Local\Temp\2c9362052ff91db960f514d041b7f4e4.mpf_cache
2025-03-21 13:47:24,703 : WARNING : ConfigProcessor : Config file in cache changed: C:\Users\duffb\OneDrive\Documents\Python Envs\PinBallWW1\Machine\modes\base\config\base.yaml
2025-03-21 13:47:24,703 : INFO : ConfigProcessor : Loading config from file C:\Users\duffb\OneDrive\Documents\Python Envs\PinBallWW1\Machine\modes\base\config\base.yaml.
2025-03-21 13:47:24,717 : INFO : ConfigProcessor : Loading config: C:\Users\duffb\OneDrive\Documents\Python Envs\PinBallWW1\Machine\modes\base\config\base.yaml
2025-03-21 13:47:24,718 : INFO : ConfigProcessor : Config file cache created: C:\Users\duffb\AppData\Local\Temp\9e006ea23aa21ec68e01f6c49afad9f4.mpf_cache
2025-03-21 13:47:24,719 : INFO : ConfigProcessor : Loading config from cache: C:\Users\duffb\AppData\Local\Temp\fd253b339e263587268891c4dd997fbd.mpf_cache
2025-03-21 13:47:24,719 : INFO : ConfigProcessor : Loading config from cache: C:\Users\duffb\AppData\Local\Temp\c114ce798d07012a33b8b14d8f953bb7.mpf_cache
2025-03-21 13:47:24,720 : INFO : ConfigProcessor : Loading config from cache: C:\Users\duffb\AppData\Local\Temp\ef70c2e65c3659b77bacdd3a7a24b233.mpf_cache
2025-03-21 13:47:24,721 : INFO : ConfigProcessor : Loading config from cache: C:\Users\duffb\AppData\Local\Temp\ec6e376f0ea10a5fdf8f7130b4bbbe7c.mpf_cache
2025-03-21 13:47:24,723 : INFO : Machine : Mission Pinball Framework Core Engine v0.57.0
2025-03-21 13:47:24,723 : INFO : Machine : Command line arguments: {'no_load_cache': False, 'create_config_cache': True, 'bcp': True, 'configfile': ['config.yaml'], 'force_assets_load': False, 'platform_integration_test': False, 'jsonlogging': False, 'logfile': 'logs\\2025-03-21-13-47-24-mpf-T0SHIII.log', 'pause': False, 'production': False, 'text_ui': True, 'loglevel': 15, 'consoleloglevel': 20, 'force_platform': None, 'syslog_address': None, 'mc_file_name': None, 'no_sound': False}
2025-03-21 13:47:24,723 : INFO : Machine : MPF path: C:\Users\duffb\.pyenv\pyenv-win\versions\3.11.0\Lib\site-packages\mpf
2025-03-21 13:47:24,723 : INFO : Machine : Machine path: C:\Users\duffb\OneDrive\Documents\Python Envs\PinBallWW1\Machine
2025-03-21 13:47:24,723 : INFO : Machine : Platform: win32
2025-03-21 13:47:24,723 : INFO : Machine : Python executable location: C:\Users\duffb\.pyenv\pyenv-win\versions\3.11.0\python.exe
2025-03-21 13:47:24,723 : INFO : Machine : Python version: 3.11.0 (64-bit)
2025-03-21 13:47:24,725 : INFO : Machine : Initializing MPF...
2025-03-21 13:47:25,012 : INFO : EventManager : Event: ======'machine_var_credits_string'====== Args={'value': 'FREE PLAY', 'prev_value': None, 'change': True}
2025-03-21 13:47:25,091 : INFO : EventManager : Event: ======'machine_var_master_volume'====== Args={'value': 0.5, 'prev_value': None, 'change': True}
2025-03-21 13:47:25,091 : INFO : EventManager : Event: ======'machine_var_player1_score'====== Args={'value': 8000, 'prev_value': None, 'change': True}
2025-03-21 13:47:25,091 : INFO : EventManager : Event: ======'machine_var_player2_score'====== Args={'value': 1000, 'prev_value': None, 'change': True}
2025-03-21 13:47:25,091 : INFO : EventManager : Event: ======'machine_var_mpf_version'====== Args={'value': 'Mission Pinball Framework v0.57.0', 'prev_value': None, 'change': True}
2025-03-21 13:47:25,091 : INFO : EventManager : Event: ======'machine_var_mpf_extended_version'====== Args={'value': 'Mission Pinball Framework v0.57.0, Config version:6, Show version: 6, BCP version:1.1', 'prev_value': None, 'change': True}
2025-03-21 13:47:25,091 : INFO : EventManager : Event: ======'machine_var_python_version'====== Args={'value': '3.11.0', 'prev_value': None, 'change': True}
2025-03-21 13:47:25,108 : INFO : EventManager : Event: ======'machine_var_platform'====== Args={'value': 'Windows-10-10.0.26100-SP0', 'prev_value': None, 'change': True}
2025-03-21 13:47:25,108 : INFO : EventManager : Event: ======'machine_var_platform_system'====== Args={'value': 'Windows', 'prev_value': None, 'change': True}
2025-03-21 13:47:25,108 : INFO : EventManager : Event: ======'machine_var_platform_release'====== Args={'value': '10', 'prev_value': None, 'change': True}
2025-03-21 13:47:25,108 : INFO : EventManager : Event: ======'machine_var_platform_version'====== Args={'value': '10.0.26100', 'prev_value': None, 'change': True}
2025-03-21 13:47:25,108 : INFO : EventManager : Event: ======'machine_var_platform_machine'====== Args={'value': 'AMD64', 'prev_value': None, 'change': True}
2025-03-21 13:47:25,108 : INFO : EventManager : Event: ======'init_phase_1'====== Args={}
2025-03-21 13:47:25,126 : ERROR : ConfigValidator : Your config contains a value for the setting "ball_devices:bd_plunger_lane:player_controlled_eject_events", but this is not a valid setting name.
2025-03-21 13:47:25,126 : ERROR : asyncio : Exception in callback EventManager._async_handler_done(<QueuedEvent>)(<Task finishe...tting name.')>) at C:\Users\duffb\.pyenv\pyenv-win\versions\3.11.0\Lib\site-packages\mpf\core\events.py:124
handle: <Handle EventManager._async_handler_done(<QueuedEvent>)(<Task finishe...tting name.')>) at C:\Users\duffb\.pyenv\pyenv-win\versions\3.11.0\Lib\site-packages\mpf\core\events.py:124>
Traceback (most recent call last):
  File "C:\Users\duffb\.pyenv\pyenv-win\versions\3.11.0\Lib\asyncio\events.py", line 80, in _run
    self._context.run(self._callback, *self._args)
  File "C:\Users\duffb\.pyenv\pyenv-win\versions\3.11.0\Lib\site-packages\mpf\core\events.py", line 127, in _async_handler_done
    future.result()
  File "C:\Users\duffb\.pyenv\pyenv-win\versions\3.11.0\Lib\site-packages\mpf\core\device_manager.py", line 88, in _load_device_modules
    self.load_devices_config(validate=True)
  File "C:\Users\duffb\.pyenv\pyenv-win\versions\3.11.0\Lib\site-packages\mpf\core\device_manager.py", line 146, in load_devices_config
    config[device_name] = collection[device_name].validate_and_parse_config(config[device_name], False)
                          ^^^^^^^^^^^^^^^^^^^^^^^^^^^^^^^^^^^^^^^^^^^^^^^^^^^^^^^^^^^^^^^^^^^^^^^^^^^^^
  File "C:\Users\duffb\.pyenv\pyenv-win\versions\3.11.0\Lib\site-packages\mpf\core\device.py", line 108, in validate_and_parse_config
    self.machine.config_validator.validate_config(
  File "C:\Users\duffb\.pyenv\pyenv-win\versions\3.11.0\Lib\site-packages\mpf\core\config_validator.py", line 164, in validate_config
    return self._validate_config(config_spec, source, base_spec=base_spec, add_missing_keys=add_missing_keys,
           ^^^^^^^^^^^^^^^^^^^^^^^^^^^^^^^^^^^^^^^^^^^^^^^^^^^^^^^^^^^^^^^^^^^^^^^^^^^^^^^^^^^^^^^^^^^^^^^^^^
  File "C:\Users\duffb\.pyenv\pyenv-win\versions\3.11.0\Lib\site-packages\mpf\core\config_validator.py", line 177, in _validate_config
    self.check_for_invalid_sections(this_spec, source, validation_failure_info)
  File "C:\Users\duffb\.pyenv\pyenv-win\versions\3.11.0\Lib\site-packages\mpf\core\config_validator.py", line 336, in check_for_invalid_sections
    raise ConfigFileError('Your config contains a value for the '
mpf.exceptions.config_file_error.ConfigFileError: Config File Error in ConfigValidator: Your config contains a value for the setting "ball_devices:bd_plunger_lane:player_controlled_eject_events", but this is not a valid setting name. Error Code: CFE-ConfigValidator-2 (https://missionpinball.org/logs)
2025-03-21 13:47:25,130 : INFO : Machine : Starting the main run loop.
2025-03-21 13:47:25,131 : INFO : Machine : Shutting down...
2025-03-21 13:47:25,131 : INFO : EventManager : Event: ======'shutdown'====== Args={}
2025-03-21 13:47:26,138 : ERROR : Machine : Runtime Exception
Traceback (most recent call last):
  File "C:\Users\duffb\.pyenv\pyenv-win\versions\3.11.0\Lib\site-packages\mpf\core\machine.py", line 794, in _run_loop
    raise self._exception['exception']
  File "C:\Users\duffb\.pyenv\pyenv-win\versions\3.11.0\Lib\asyncio\events.py", line 80, in _run
    self._context.run(self._callback, *self._args)
  File "C:\Users\duffb\.pyenv\pyenv-win\versions\3.11.0\Lib\site-packages\mpf\core\events.py", line 127, in _async_handler_done
    future.result()
  File "C:\Users\duffb\.pyenv\pyenv-win\versions\3.11.0\Lib\site-packages\mpf\core\device_manager.py", line 88, in _load_device_modules
    self.load_devices_config(validate=True)
  File "C:\Users\duffb\.pyenv\pyenv-win\versions\3.11.0\Lib\site-packages\mpf\core\device_manager.py", line 146, in load_devices_config
    config[device_name] = collection[device_name].validate_and_parse_config(config[device_name], False)
                          ^^^^^^^^^^^^^^^^^^^^^^^^^^^^^^^^^^^^^^^^^^^^^^^^^^^^^^^^^^^^^^^^^^^^^^^^^^^^^
  File "C:\Users\duffb\.pyenv\pyenv-win\versions\3.11.0\Lib\site-packages\mpf\core\device.py", line 108, in validate_and_parse_config
    self.machine.config_validator.validate_config(
  File "C:\Users\duffb\.pyenv\pyenv-win\versions\3.11.0\Lib\site-packages\mpf\core\config_validator.py", line 164, in validate_config
    return self._validate_config(config_spec, source, base_spec=base_spec, add_missing_keys=add_missing_keys,
           ^^^^^^^^^^^^^^^^^^^^^^^^^^^^^^^^^^^^^^^^^^^^^^^^^^^^^^^^^^^^^^^^^^^^^^^^^^^^^^^^^^^^^^^^^^^^^^^^^^
  File "C:\Users\duffb\.pyenv\pyenv-win\versions\3.11.0\Lib\site-packages\mpf\core\config_validator.py", line 177, in _validate_config
    self.check_for_invalid_sections(this_spec, source, validation_failure_info)
  File "C:\Users\duffb\.pyenv\pyenv-win\versions\3.11.0\Lib\site-packages\mpf\core\config_validator.py", line 336, in check_for_invalid_sections
    raise ConfigFileError('Your config contains a value for the '
mpf.exceptions.config_file_error.ConfigFileError: Config File Error in ConfigValidator: Your config contains a value for the setting "ball_devices:bd_plunger_lane:player_controlled_eject_events", but this is not a valid setting name. Error Code: CFE-ConfigValidator-2 (https://missionpinball.org/logs)
2025-03-21 13:47:43,847 : ERROR : root : 
Traceback (most recent call last):
  File "C:\Users\duffb\.pyenv\pyenv-win\versions\3.11.0\Lib\site-packages\mpf\core\machine.py", line 794, in _run_loop
    raise self._exception['exception']
  File "C:\Users\duffb\.pyenv\pyenv-win\versions\3.11.0\Lib\asyncio\events.py", line 80, in _run
    self._context.run(self._callback, *self._args)
  File "C:\Users\duffb\.pyenv\pyenv-win\versions\3.11.0\Lib\site-packages\mpf\core\events.py", line 127, in _async_handler_done
    future.result()
  File "C:\Users\duffb\.pyenv\pyenv-win\versions\3.11.0\Lib\site-packages\mpf\core\device_manager.py", line 88, in _load_device_modules
    self.load_devices_config(validate=True)
  File "C:\Users\duffb\.pyenv\pyenv-win\versions\3.11.0\Lib\site-packages\mpf\core\device_manager.py", line 146, in load_devices_config
    config[device_name] = collection[device_name].validate_and_parse_config(config[device_name], False)
                          ^^^^^^^^^^^^^^^^^^^^^^^^^^^^^^^^^^^^^^^^^^^^^^^^^^^^^^^^^^^^^^^^^^^^^^^^^^^^^
  File "C:\Users\duffb\.pyenv\pyenv-win\versions\3.11.0\Lib\site-packages\mpf\core\device.py", line 108, in validate_and_parse_config
    self.machine.config_validator.validate_config(
  File "C:\Users\duffb\.pyenv\pyenv-win\versions\3.11.0\Lib\site-packages\mpf\core\config_validator.py", line 164, in validate_config
    return self._validate_config(config_spec, source, base_spec=base_spec, add_missing_keys=add_missing_keys,
           ^^^^^^^^^^^^^^^^^^^^^^^^^^^^^^^^^^^^^^^^^^^^^^^^^^^^^^^^^^^^^^^^^^^^^^^^^^^^^^^^^^^^^^^^^^^^^^^^^^
  File "C:\Users\duffb\.pyenv\pyenv-win\versions\3.11.0\Lib\site-packages\mpf\core\config_validator.py", line 177, in _validate_config
    self.check_for_invalid_sections(this_spec, source, validation_failure_info)
  File "C:\Users\duffb\.pyenv\pyenv-win\versions\3.11.0\Lib\site-packages\mpf\core\config_validator.py", line 336, in check_for_invalid_sections
    raise ConfigFileError('Your config contains a value for the '
mpf.exceptions.config_file_error.ConfigFileError: Config File Error in ConfigValidator: Your config contains a value for the setting "ball_devices:bd_plunger_lane:player_controlled_eject_events", but this is not a valid setting name. Error Code: CFE-ConfigValidator-2 (https://missionpinball.org/logs)

During handling of the above exception, another exception occurred:

Traceback (most recent call last):
  File "C:\Users\duffb\.pyenv\pyenv-win\versions\3.11.0\Lib\site-packages\mpf\commands\game.py", line 240, in __init__
    self.machine.run()
  File "C:\Users\duffb\.pyenv\pyenv-win\versions\3.11.0\Lib\site-packages\mpf\core\machine.py", line 690, in run
    self._run_loop()
  File "C:\Users\duffb\.pyenv\pyenv-win\versions\3.11.0\Lib\site-packages\mpf\core\machine.py", line 797, in _run_loop
    report_crash(self._exception['exception'], "exception_during_run", self.config)
  File "C:\Users\duffb\.pyenv\pyenv-win\versions\3.11.0\Lib\site-packages\mpf\core\crash_reporter.py", line 236, in report_crash
    response = input("Do you want to report the crash to the MPF team (yes/no/show)? ")
               ^^^^^^^^^^^^^^^^^^^^^^^^^^^^^^^^^^^^^^^^^^^^^^^^^^^^^^^^^^^^^^^^^^^^^^^^
EOFError
