2025-03-22 22:14:02,021 : INFO : root : Loading config.
2025-03-22 22:14:02,025 : INFO : YamlMultifileConfigLoader : Machine config file #1: config.yaml
2025-03-22 22:14:02,025 : WARNING : ConfigProcessor : Config file in cache changed: C:\Users\duffb\OneDrive\Documents\Python Envs\PinBallWW1\Machine\config\config.yaml
2025-03-22 22:14:02,025 : INFO : ConfigProcessor : Loading config from file C:\Users\duffb\.pyenv\pyenv-win\versions\3.11.0\Lib\site-packages\mpf\mpfconfig.yaml.
2025-03-22 22:14:02,036 : INFO : ConfigProcessor : Loading config: C:\Users\duffb\.pyenv\pyenv-win\versions\3.11.0\Lib\site-packages\mpf\mpfconfig.yaml
2025-03-22 22:14:02,036 : INFO : ConfigProcessor : Loading config from file C:\Users\duffb\OneDrive\Documents\Python Envs\PinBallWW1\Machine\config\config.yaml.
2025-03-22 22:14:02,058 : INFO : ConfigProcessor : Loading config: C:\Users\duffb\OneDrive\Documents\Python Envs\PinBallWW1\Machine\config\config.yaml
2025-03-22 22:14:09,481 : ERROR : root : Shutdown because of SIGINT or keyboard interrupt.
Traceback (most recent call last):
  File "C:\Users\duffb\.pyenv\pyenv-win\versions\3.11.0\Lib\site-packages\mpf\commands\game.py", line 231, in __init__
    config = config_loader.load_mpf_config()
             ^^^^^^^^^^^^^^^^^^^^^^^^^^^^^^^
  File "C:\Users\duffb\.pyenv\pyenv-win\versions\3.11.0\Lib\site-packages\mpf\core\config_loader.py", line 164, in load_mpf_config
    machine_config = self._load_mpf_machine_config(config_spec)
                     ^^^^^^^^^^^^^^^^^^^^^^^^^^^^^^^^^^^^^^^^^^
  File "C:\Users\duffb\.pyenv\pyenv-win\versions\3.11.0\Lib\site-packages\mpf\core\config_loader.py", line 188, in _load_mpf_machine_config
    return self.config_processor.load_config_files_with_cache(config_files, "machine", config_spec=config_spec)
           ^^^^^^^^^^^^^^^^^^^^^^^^^^^^^^^^^^^^^^^^^^^^^^^^^^^^^^^^^^^^^^^^^^^^^^^^^^^^^^^^^^^^^^^^^^^^^^^^^^^^
  File "C:\Users\duffb\.pyenv\pyenv-win\versions\3.11.0\Lib\site-packages\mpf\core\config_processor.py", line 118, in load_config_files_with_cache
    file_config, file_subfiles = self._load_config_file_and_return_loaded_files(configfile, config_type,
                                 ^^^^^^^^^^^^^^^^^^^^^^^^^^^^^^^^^^^^^^^^^^^^^^^^^^^^^^^^^^^^^^^^^^^^^^^
  File "C:\Users\duffb\.pyenv\pyenv-win\versions\3.11.0\Lib\site-packages\mpf\core\config_processor.py", line 186, in _load_config_file_and_return_loaded_files
    self._check_sections(config_spec, config, config_type, filename, ignore_unknown_sections)
  File "C:\Users\duffb\.pyenv\pyenv-win\versions\3.11.0\Lib\site-packages\mpf\core\config_processor.py", line 163, in _check_sections
    raise ConfigFileError('Found a "{}:" section in config file {}, '
mpf.exceptions.config_file_error.ConfigFileError: Config File Error in ConfigProcessor: Found a "events:" section in config file C:\Users\duffb\OneDrive\Documents\Python Envs\PinBallWW1\Machine\config\config.yaml, but that section name is unknown. Did you mean "event_player:" instead?. Context: C:\Users\duffb\OneDrive\Documents\Python Envs\PinBallWW1\Machine\config\config.yaml Error Code: CFE-ConfigProcessor-3 (https://missionpinball.org/logs)
